Workbook
Name Slicer_Crop_Type: #N/A
Name Slicer_Crop_Type1: #N/A
Name Slicer_Distict: #N/A
Name Slicer_Districts: #N/A
Name Slicer_Irrigation_Type: #N/A
Name Slicer_Rainfall_bands: #N/A
Name Slicer_Season: #N/A
Name Slicer_Soil_Type: #N/A
Name Slicer_Soil_types: #N/A
Name Slicer_Year: #N/A
Name Slicer_Year1: #N/A

Sheet Cover

Sheet Executive Summary

Sheet RAW DATA
A1: Record_ID | B1: District | C1: Crop_Type | D1: Season | E1: Soil_Type | F1: Rainfall_mm | G1: Temperature_Celsius | H1: Irrigation_Type | I1: Input_Cost_INR | J1: Yield_Quintal_per_Hectare | K1: Farmer_ID | L1: Year
A2: REC001 | B2: Cuttack | C2: Rice | D2: Zaid | E2: Red | F2: 273.5 | G2: 31.7 | H2: Rainfed | I2: 60106 | J2: 13.9 | K2: F006 | L2: 2023
A3: REC002 | B3: Kendrapara | C3: Rice | D3: Kharif | E3: Alluvial | F3: 1018.6 | G3: 29.6 | H3: Rainfed | I3: 51216 | J3: 38.1 | K3: F045 | L3: 2023
A4: REC003 | B4: Kendrapara | C4: Sugarcane | D4: Rabi | E4: Sandy | F4: 339.1 | G4: 26.7 | H4: Canal | I4: 61757 | J4: 7.2 | K4: F010 | L4: 2021
A5: REC004 | B5: Sambalpur | C5: Wheat | D5: Kharif | E5: Laterite | F5: 896.7 | G5: 33.3 | H5: Drip | I5: 70149 | J5: 22.2 | K5: F035 | L5: 2021
A6: REC005 | B6: Kendrapara | C6: Wheat | D6: Zaid | E6: Red | F6: 448.8 | G6: 37.4 | H6: Drip | I6: 52456 | J6: 15.5 | K6: F003 | L6: 2023
A7: REC006 | B7: Ganjam | C7: Cotton | D7: Kharif | E7: Black | F7: 1666.5 | G7: 28.2 | H7: Sprinkler | I7: 56948 | J7: 49.1 | K7: F024 | L7: 2022
A8: REC007 | B8: Ganjam | C8: Cotton | D8: Zaid | E8: Alluvial | F8: 382.7 | G8: 32.1 | H8: Canal | I8: 20582 | J8: 16.4 | K8: F041 | L8: 2023
A9: REC008 | B9: Bhadrak | C9: Sugarcane | D9: Zaid | E9: Red | F9: 452.9 | G9: 39.3 | H9: Canal | I9: 71279 | J9: 16.6 | K9: F026 | L9: 2022
A10: REC009 | B10: Cuttack | C10: Sugarcane | D10: Zaid | E10: Red | F10: 263.8 | G10: 36 | H10: Sprinkler | I10: 19001 | J10: 6.2 | K10: F048 | L10: 2023
A11: REC010 | B11: Bhadrak | C11: Cotton | D11: Zaid | E11: Sandy | F11: 328.5 | G11: 37 | H11: Drip | I11: 24888 | J11: unknown | K11: F033 | L11: 2022
A12: REC011 | B12: Cuttack | C12: Rice | D12: Kharif | E12: Black | F12: 1427.4 | G12: 32.7 | H12: Sprinkler | I12: 53923 | J12: 42.9 | K12: F039 | L12: 2022
A13: REC012 | B13: Bhadrak | C13: Cotton | D13: Zaid | E13: Alluvial | F13: 404.1 | G13: 31.4 | H13: Drip | I13: 67182 | J13: 16.6 | K13: F019 | L13: 2022
A14: REC013 | B14: Puri | C14: Pulses | D14: Kharif | E14: Red | F14: 1771.9 | G14: 32.4 | H14: Rainfed | I14: 75030 | J14: 37.9 | K14: F041 | L14: 2023
A15: REC014 | B15: Angul | C15: Sugarcane | D15: Kharif | E15: Red | F15: 1562.5 | G15: 29.9 | H15: rainfed | I15: 54119 | J15: 35.6 | K15: F008 | L15: 2022
A16: REC015 | B16: Balasore | C16: Sugarcane | D16: Kharif | E16: Black | F16: 1678 | G16: 34.4 | H16: RAINFED | I16: 64357 | J16: 53.9 | K16: F049 | L16: 2023
A17: REC016 | B17: Puri | C17: Maize | D17: Zaid | E17: Laterite | F17: 484.1 | G17: 32 | H17: SPRINKLER | I17: 82256 | J17: 16.9 | K17: F049 | L17: 2023
A18: REC017 | B18: Ganjam | C18: Cotton | D18: Rabi | E18: Red | F18: 419.1 | G18: 23.2 | H18: Rainfed | I18: 27089 | J18: 8.5 | K18: F002 | L18: 2023
A19: REC018 | B19: Bhadrak | C19: Sugarcane | D19: Zaid | E19: Black | F19: 202.2 | H19: Rainfed | I19: 25629 | J19: 15.4 | K19: F022 | L19: 2021
A20: REC019 | B20: Bhadrak | C20: Sugarcane | D20: Rabi | E20: Laterite | F20: 307.1 | G20: 19.3 | H20: Sprinkler | I20: 26711 | J20: 9.2 | K20: F027 | L20: 2021
A21: REC020 | B21: Cuttack | C21: Wheat | D21: Zaid | E21: Laterite | F21: 306.3 | G21: 34.9 | H21: rainfed | I21: 59849 | J21: 14.3 | K21: F007 | L21: 2021
A22: REC021 | B22: Kendrapara | C22: Groundnut | D22: Kharif | E22: Black | F22: 991.6 | G22: 29.9 | H22: Canal | I22: 40485 | J22: 30.2 | K22: F016 | L22: 2021
A23: REC022 | B23: Jajpur | C23: Wheat | D23: Kharif | E23: Sandy | F23: 1636 | G23: 34.7 | H23: Canal | I23: 20806 | J23: 28.8 | K23: F014 | L23: 2022
A24: REC023 | B24: Khordha | C24: Maize | D24: Rabi | E24: Alluvial | F24: 692.7 | G24: 20.7 | H24: Sprinkler | I24: 29964 | J24: 28.5 | K24: F047 | L24: 2023
A25: REC024 | B25: Jajpur | C25: Maize | D25: Kharif | E25: Red | F25: 1017.7 | G25: 24.6 | H25: Rainfed | I25: 65594 | J25: 20.4 | K25: F038 | L25: 2022
A26: REC025 | B26: Bhadrak | C26: Maize | D26: Kharif | E26: Sandy | F26: 880.1 | G26: 26 | H26: Rainfed | I26: 59991 | J26: 14.5 | K26: F008 | L26: 2023
A27: REC026 | B27: Ganjam | C27: Rice | D27: Zaid | E27: Alluvial | F27: 325.8 | G27: 37 | H27: Drip | I27: 79972 | J27: 13 | K27: F046 | L27: 2022
A28: REC027 | B28: Ganjam | C28: Cotton | D28: Rabi | E28: Black | F28: 535.8 | G28: 21 | H28: Drip | I28: 79534 | J28: 24.6 | K28: F001 | L28: 2022
A29: REC028 | B29: Angul | C29: Wheat | D29: Kharif | E29: Sandy | F29: 1013.2 | G29: 26.9 | H29: Drip | I29: 75827 | J29: 23.1 | K29: F024 | L29: 2022
A30: REC029 | B30: Puri | C30: Pulses | D30: Zaid | E30: Red | F30: 383.5 | G30: 41.8 | H30: RAINFED | I30: 59425 | J30: 12.7 | K30: F043 | L30: 2021
A31: REC030 | B31: Puri | C31: Cotton | D31: Kharif | E31: Alluvial | F31: 1542.4 | G31: 25.7 | H31: drip | I31: 54572 | J31: 53.2 | K31: F014 | L31: 2023
... A77: REC076 | B77: Angul | C77: Cotton | D77: Rabi | E77: Alluvial | F77: 434.3 | G77: 21 | H77: Sprinkler | I77: 80586 | J77: 19.1 | K77: F032 | L77: 2022
A78: REC077 | B78: Cuttack | C78: Rice | D78: Rabi | E78: Red | G78: 18.3 | H78: Canal | I78: 82067 | J78: 17.9 | K78: F037 | L78: 2023
A79: REC078 | B79: Khordha | C79: Cotton | D79: Zaid | E79: Alluvial | F79: 428.9 | G79: 32.1 | H79: Sprinkler | I79: 78538 | J79: 15.7 | K79: F038 | L79: 2022
A80: REC079 | B80: Jajpur | C80: Wheat | D80: Rabi | E80: Red | F80: 404.2 | G80: 21.2 | H80: Rainfed | I80: 74045 | J80: 10.9 | K80: F045 | L80: 2022
A81: REC080 | B81: Balasore | C81: Soybean | D81: Zaid | E81: Alluvial | F81: 336.4 | G81: 33.8 | H81: Drip | I81: 16926 | J81: 18.9 | K81: F033 | L81: 2021
A82: REC081 | B82: Bhadrak | C82: Pulses | D82: Rabi | E82: Alluvial | F82: 293.8 | G82: 21.6 | H82: Sprinkler | I82: 56156 | J82: 17.6 | K82: F014 | L82: 2022
A83: REC082 | B83: Bhadrak | C83: Maize | D83: Rabi | E83: Laterite | F83: 640.4 | G83: 22.8 | H83: rainfed | I83: 82932 | J83: 16.5 | K83: F016 | L83: 2023
A84: REC083 | B84: Puri | C84: Cotton | D84: Zaid | E84: Alluvial | F84: 365.7 | G84: 31.1 | H84: Rainfed | I84: 43531 | J84: 13.2 | K84: F010 | L84: 2022
A85: REC084 | B85: Balasore | C85: Cotton | D85: Rabi | E85: Laterite | F85: 690.1 | G85: 20.4 | H85: Canal | I85: 37536 | J85: 20.5 | K85: F033 | L85: 2023
...

Sheet Clean_Data
A1: Record_ID | B1: District | C1: Crop_Type | D1: Season | E1: Soil_Type | F1: Rainfall_mm | G1: Temperature_Celsius | H1: Irrigation_Type | I1: Input_Cost_INR | J1: Yield_Quintal_per_Hectare | K1: Farmer_ID | L1: Year | M1: Rainfall Bands | N1: Performance'.
A2: REC001 | B2: Cuttack | C2: Rice | D2: Zaid | E2: Red | F2: 273.5 | G2: 31.7 | H2: Rainfed | I2: 60106 | J2: 13.9 | K2: F006 | L2: 2023 | M2: =IF(F2<400,"Low(<400mm)",IF(AND(F2>=400,F2<=900),"Medium(400-900mm)","High(>900mm)")) -> Low(<400mm) | N2: =IF(J2<25,"Low Yield(<25)",IF(AND(J2>=25,J2<=40),"Medium Yield(25-40)",IF(AND(J2>40,J2<=55),"High Yield(40-55)","Exceptional Yield(>55)"))) -> Low Yield(<25)
A3: REC002 | B3: Kendrapara | C3: Rice | D3: Kharif | E3: Alluvial | F3: 1018.6 | G3: 29.6 | H3: Rainfed | I3: 51216 | J3: 38.1 | K3: F045 | L3: 2023 | M3: =IF(F3<400,"Low(<400mm)",IF(AND(F3>=400,F3<=900),"Medium(400-900mm)","High(>900mm)")) -> High(>900mm) | N3: =IF(J3<25,"Low Yield(<25)",IF(AND(J3>=25,J3<=40),"Medium Yield(25-40)",IF(AND(J3>40,J3<=55),"High Yield(40-55)","Exceptional Yield(>55)"))) -> Medium Yield(25-40)
A4: REC003 | B4: Kendrapara | C4: Sugarcane | D4: Rabi | E4: Sandy | F4: 339.1 | G4: 26.7 | H4: Canal | I4: 61757 | J4: 7.2 | K4: F010 | L4: 2021 | M4: =IF(F4<400,"Low(<400mm)",IF(AND(F4>=400,F4<=900),"Medium(400-900mm)","High(>900mm)")) -> Low(<400mm) | N4: =IF(J4<25,"Low Yield(<25)",IF(AND(J4>=25,J4<=40),"Medium Yield(25-40)",IF(AND(J4>40,J4<=55),"High Yield(40-55)","Exceptional Yield(>55)"))) -> Low Yield(<25)
A5: REC004 | B5: Sambalpur | C5: Wheat | D5: Kharif | E5: Laterite | F5: 896.7 | G5: 33.3 | H5: Drip | I5: 70149 | J5: 22.2 | K5: F035 | L5: 2021 | M5: =IF(F5<400,"Low(<400mm)",IF(AND(F5>=400,F5<=900),"Medium(400-900mm)","High(>900mm)")) -> Medium(400-900mm) | N5: =IF(J5<25,"Low Yield(<25)",IF(AND(J5>=25,J5<=40),"Medium Yield(25-40)",IF(AND(J5>40,J5<=55),"High Yield(40-55)","Exceptional Yield(>55)"))) -> Low Yield(<25)
A6: REC005 | B6: Kendrapara | C6: Wheat | D6: Zaid | E6: Red | F6: 448.8 | G6: 37.4 | H6: Drip | I6: 52456 | J6: 15.5 | K6: F003 | L6: 2023 | M6: =IF(F6<400,"Low(<400mm)",IF(AND(F6>=400,F6<=900),"Medium(400-900mm)","High(>900mm)")) -> Medium(400-900mm) | N6: =IF(J6<25,"Low Yield(<25)",IF(AND(J6>=25,J6<=40),"Medium Yield(25-40)",IF(AND(J6>40,J6<=55),"High Yield(40-55)","Exceptional Yield(>55)"))) -> Low Yield(<25)
A7: REC006 | B7: Ganjam | C7: Cotton | D7: Kharif | E7: Black | F7: 1666.5 | G7: 28.2 | H7: Sprinkler | I7: 56948 | J7: 49.1 | K7: F024 | L7: 2022 | M7: =IF(F7<400,"Low(<400mm)",IF(AND(F7>=400,F7<=900),"Medium(400-900mm)","High(>900mm)")) -> High(>900mm) | N7: =IF(J7<25,"Low Yield(<25)",IF(AND(J7>=25,J7<=40),"Medium Yield(25-40)",IF(AND(J7>40,J7<=55),"High Yield(40-55)","Exceptional Yield(>55)"))) -> High Yield(40-55)
A8: REC007 | B8: Ganjam | C8: Cotton | D8: Zaid | E8: Alluvial | F8: 382.7 | G8: 32.1 | H8: Canal | I8: 20582 | J8: 16.4 | K8: F041 | L8: 2023 | M8: =IF(F8<400,"Low(<400mm)",IF(AND(F8>=400,F8<=900),"Medium(400-900mm)","High(>900mm)")) -> Low(<400mm) | N8: =IF(J8<25,"Low Yield(<25)",IF(AND(J8>=25,J8<=40),"Medium Yield(25-40)",IF(AND(J8>40,J8<=55),"High Yield(40-55)","Exceptional Yield(>55)"))) -> Low Yield(<25)
A9: REC008 | B9: Bhadrak | C9: Sugarcane | D9: Zaid | E9: Red | F9: 452.9 | G9: 39.3 | H9: Canal | I9: 71279 | J9: 16.6 | K9: F026 | L9: 2022 | M9: =IF(F9<400,"Low(<400mm)",IF(AND(F9>=400,F9<=900),"Medium(400-900mm)","High(>900mm)")) -> Medium(400-900mm) | N9: =IF(J9<25,"Low Yield(<25)",IF(AND(J9>=25,J9<=40),"Medium Yield(25-40)",IF(AND(J9>40,J9<=55),"High Yield(40-55)","Exceptional Yield(>55)"))) -> Low Yield(<25)
A10: REC009 | B10: Cuttack | C10: Sugarcane | D10: Zaid | E10: Red | F10: 263.8 | G10: 36 | H10: Sprinkler | I10: 19001 | J10: 6.2 | K10: F048 | L10: 2023 | M10: =IF(F10<400,"Low(<400mm)",IF(AND(F10>=400,F10<=900),"Medium(400-900mm)","High(>900mm)")) -> Low(<400mm) | N10: =IF(J10<25,"Low Yield(<25)",IF(AND(J10>=25,J10<=40),"Medium Yield(25-40)",IF(AND(J10>40,J10<=55),"High Yield(40-55)","Exceptional Yield(>55)"))) -> Low Yield(<25)
A11: REC010 | B11: Bhadrak | C11: Cotton | D11: Zaid | E11: Sandy | F11: 328.5 | G11: 37 | H11: Drip | I11: 24888 | J11: 0 | K11: F033 | L11: 2022 | M11: =IF(F11<400,"Low(<400mm)",IF(AND(F11>=400,F11<=900),"Medium(400-900mm)","High(>900mm)")) -> Low(<400mm) | N11: =IF(J11<25,"Low Yield(<25)",IF(AND(J11>=25,J11<=40),"Medium Yield(25-40)",IF(AND(J11>40,J11<=55),"High Yield(40-55)","Exceptional Yield(>55)"))) -> Low Yield(<25)
A12: REC011 | B12: Cuttack | C12: Rice | D12: Kharif | E12: Black | F12: 1427.4 | G12: 32.7 | H12: Sprinkler | I12: 53923 | J12: 42.9 | K12: F039 | L12: 2022 | M12: =IF(F12<400,"Low(<400mm)",IF(AND(F12>=400,F12<=900),"Medium(400-900mm)","High(>900mm)")) -> High(>900mm) | N12: =IF(J12<25,"Low Yield(<25)",IF(AND(J12>=25,J12<=40),"Medium Yield(25-40)",IF(AND(J12>40,J12<=55),"High Yield(40-55)","Exceptional Yield(>55)"))) -> High Yield(40-55)
A13: REC012 | B13: Bhadrak | C13: Cotton | D13: Zaid | E13: Alluvial | F13: 404.1 | G13: 31.4 | H13: Drip | I13: 67182 | J13: 16.6 | K13: F019 | L13: 2022 | M13: =IF(F13<400,"Low(<400mm)",IF(AND(F13>=400,F13<=900),"Medium(400-900mm)","High(>900mm)")) -> Medium(400-900mm) | N13: =IF(J13<25,"Low Yield(<25)",IF(AND(J13>=25,J13<=40),"Medium Yield(25-40)",IF(AND(J13>40,J13<=55),"High Yield(40-55)","Exceptional Yield(>55)"))) -> Low Yield(<25)
... A301: REC300 | B301: Angul | C301: Soybean | D301: Zaid | E301: Laterite | F301: 348.8 | G301: 34.6 | H301: Sprinkler | I301: 21306 | J301: 7.3 | K301: F012 | L301: 2022 | M301: =IF(F301<400,"Low(<400mm)",IF(AND(F301>=400,F301<=900),"Medium(400-900mm)","High(>900mm)")) -> Low(<400mm) | N301: =IF(J301<25,"Low Yield(<25)",IF(AND(J301>=25,J301<=40),"Medium Yield(25-40)",IF(AND(J301>40,J301<=55),"High Yield(40-55)","Exceptional Yield(>55)"))) -> Low Yield(<25)

Sheet Analysis
A6: District-wise Average Yield
A7: Districts | B7: Average yield | C7: No.of Records Exist per District
A8: Cuttack | B8: =AVERAGEIF(Clean_Data!$B$2:$B$301,Analysis!A8,Clean_Data!$J$2:$J$301) -> 21.618519 | C8: =COUNTIF(Clean_Data!$B$2:$B$301,Analysis!A8) -> 27
A9: Kendrapara | B9: =AVERAGEIF(Clean_Data!$B$2:$B$301,Analysis!A9,Clean_Data!$J$2:$J$301) -> 22.216 | C9: =COUNTIF(Clean_Data!$B$2:$B$301,Analysis!A9) -> 25
A10: Sambalpur | B10: =AVERAGEIF(Clean_Data!$B$2:$B$301,Analysis!A10,Clean_Data!$J$2:$J$301) -> 19.359375 | C10: =COUNTIF(Clean_Data!$B$2:$B$301,Analysis!A10) -> 32
A11: Ganjam | B11: =AVERAGEIF(Clean_Data!$B$2:$B$301,Analysis!A11,Clean_Data!$J$2:$J$301) -> 18.562069 | C11: =COUNTIF(Clean_Data!$B$2:$B$301,Analysis!A11) -> 29
A12: Bhadrak | B12: =AVERAGEIF(Clean_Data!$B$2:$B$301,Analysis!A12,Clean_Data!$J$2:$J$301) -> 19.537778 | C12: =COUNTIF(Clean_Data!$B$2:$B$301,Analysis!A12) -> 45
A13: Puri | B13: =AVERAGEIF(Clean_Data!$B$2:$B$301,Analysis!A13,Clean_Data!$J$2:$J$301) -> 20.86 | C13: =COUNTIF(Clean_Data!$B$2:$B$301,Analysis!A13) -> 30
A14: Angul | B14: =AVERAGEIF(Clean_Data!$B$2:$B$301,Analysis!A14,Clean_Data!$J$2:$J$301) -> 20.627586 | C14: =COUNTIF(Clean_Data!$B$2:$B$301,Analysis!A14) -> 29
A15: Balasore | B15: =AVERAGEIF(Clean_Data!$B$2:$B$301,Analysis!A15,Clean_Data!$J$2:$J$301) -> 18.886667 | C15: =COUNTIF(Clean_Data!$B$2:$B$301,Analysis!A15) -> 30
A16: Jajpur | B16: =AVERAGEIF(Clean_Data!$B$2:$B$301,Analysis!A16,Clean_Data!$J$2:$J$301) -> 17.867857 | C16: =COUNTIF(Clean_Data!$B$2:$B$301,Analysis!A16) -> 28
A17: Khordha | B17: =AVERAGEIF(Clean_Data!$B$2:$B$301,Analysis!A17,Clean_Data!$J$2:$J$301) -> 19.9 | C17: =COUNTIF(Clean_Data!$B$2:$B$301,Analysis!A17) -> 25
A25: Crop Performance(average yield) by Season
A26: Crop_Type | B26: Rabi | C26: Zaid | D26: Kharif
A27: Rice | B27: =AVERAGEIFS(Clean_Data!$J$2:$J$301,Clean_Data!$C$2:$C$301,Analysis!$A27,Clean_Data!$D$2:$D$301,Analysis!$B$26) -> 15.76 | C27: =AVERAGEIFS(Clean_Data!$J$2:$J$301,Clean_Data!$C$2:$C$301,Analysis!$A27,Clean_Data!$D$2:$D$301,$C$26) -> 12.66 | D27: =AVERAGEIFS(Clean_Data!$J$2:$J$301,Clean_Data!$C$2:$C$301,Analysis!$A27,Clean_Data!$D$2:$D$301,$D$26) -> 29.208333
A28: Sugarcane | B28: =AVERAGEIFS(Clean_Data!$J$2:$J$301,Clean_Data!$C$2:$C$301,Analysis!$A28,Clean_Data!$D$2:$D$301,Analysis!$B$26) -> 14.863158 | C28: =AVERAGEIFS(Clean_Data!$J$2:$J$301,Clean_Data!$C$2:$C$301,Analysis!$A28,Clean_Data!$D$2:$D$301,$C$26) -> 10.45 | D28: =AVERAGEIFS(Clean_Data!$J$2:$J$301,Clean_Data!$C$2:$C$301,Analysis!$A28,Clean_Data!$D$2:$D$301,$D$26) -> 37.183333
A29: Wheat | B29: =AVERAGEIFS(Clean_Data!$J$2:$J$301,Clean_Data!$C$2:$C$301,Analysis!$A29,Clean_Data!$D$2:$D$301,Analysis!$B$26) -> 15.91 | C29: =AVERAGEIFS(Clean_Data!$J$2:$J$301,Clean_Data!$C$2:$C$301,Analysis!$A29,Clean_Data!$D$2:$D$301,$C$26) -> 11.766667 | D29: =AVERAGEIFS(Clean_Data!$J$2:$J$301,Clean_Data!$C$2:$C$301,Analysis!$A29,Clean_Data!$D$2:$D$301,$D$26) -> 31.7
A30: Cotton | B30: =AVERAGEIFS(Clean_Data!$J$2:$J$301,Clean_Data!$C$2:$C$301,Analysis!$A30,Clean_Data!$D$2:$D$301,Analysis!$B$26) -> 16.263636 | C30: =AVERAGEIFS(Clean_Data!$J$2:$J$301,Clean_Data!$C$2:$C$301,Analysis!$A30,Clean_Data!$D$2:$D$301,$C$26) -> 13.630769 | D30: =AVERAGEIFS(Clean_Data!$J$2:$J$301,Clean_Data!$C$2:$C$301,Analysis!$A30,Clean_Data!$D$2:$D$301,$D$26) -> 37.175
A31: Pulses | B31: =AVERAGEIFS(Clean_Data!$J$2:$J$301,Clean_Data!$C$2:$C$301,Analysis!$A31,Clean_Data!$D$2:$D$301,Analysis!$B$26) -> 12.7 | C31: =AVERAGEIFS(Clean_Data!$J$2:$J$301,Clean_Data!$C$2:$C$301,Analysis!$A31,Clean_Data!$D$2:$D$301,$C$26) -> 12.345455 | D31: =AVERAGEIFS(Clean_Data!$J$2:$J$301,Clean_Data!$C$2:$C$301,Analysis!$A31,Clean_Data!$D$2:$D$301,$D$26) -> 30.170588
A32: Maize | B32: =AVERAGEIFS(Clean_Data!$J$2:$J$301,Clean_Data!$C$2:$C$301,Analysis!$A32,Clean_Data!$D$2:$D$301,Analysis!$B$26) -> 16.306667 | C32: =AVERAGEIFS(Clean_Data!$J$2:$J$301,Clean_Data!$C$2:$C$301,Analysis!$A32,Clean_Data!$D$2:$D$301,$C$26) -> 11.6 | D32: =AVERAGEIFS(Clean_Data!$J$2:$J$301,Clean_Data!$C$2:$C$301,Analysis!$A32,Clean_Data!$D$2:$D$301,$D$26) -> 32.658333
A33: Groundnut | B33: =AVERAGEIFS(Clean_Data!$J$2:$J$301,Clean_Data!$C$2:$C$301,Analysis!$A33,Clean_Data!$D$2:$D$301,Analysis!$B$26) -> 15.269231 | C33: =AVERAGEIFS(Clean_Data!$J$2:$J$301,Clean_Data!$C$2:$C$301,Analysis!$A33,Clean_Data!$D$2:$D$301,$C$26) -> 15.96 | D33: =AVERAGEIFS(Clean_Data!$J$2:$J$301,Clean_Data!$C$2:$C$301,Analysis!$A33,Clean_Data!$D$2:$D$301,$D$26) -> 32.407692
A34: Soybean | B34: =AVERAGEIFS(Clean_Data!$J$2:$J$301,Clean_Data!$C$2:$C$301,Analysis!$A34,Clean_Data!$D$2:$D$301,Analysis!$B$26) -> 18.645455 | C34: =AVERAGEIFS(Clean_Data!$J$2:$J$301,Clean_Data!$C$2:$C$301,Analysis!$A34,Clean_Data!$D$2:$D$301,$C$26) -> 12.878571 | D34: =AVERAGEIFS(Clean_Data!$J$2:$J$301,Clean_Data!$C$2:$C$301,Analysis!$A34,Clean_Data!$D$2:$D$301,$D$26) -> 35.48
A43: Soil Type Productivity
A44: Soil types | B44: Average yield | C44: Average input cost | D44: Yield/Rs 1000 Spent
A45: Red | B45: =AVERAGEIF(Clean_Data!$E$2:$E$301,Analysis!$A45,Clean_Data!$J$2:$J$301) -> 18.645098 | C45: =AVERAGEIF(Clean_Data!$E$2:$E$301,Analysis!$A45,Clean_Data!$I$2:$I$301) -> 48619.98 | D45: =B45/(C45/1000) -> 0.38348633
A46: Alluvial | B46: =AVERAGEIF(Clean_Data!$E$2:$E$301,Analysis!$A46,Clean_Data!$J$2:$J$301) -> 22.992754 | C46: =AVERAGEIF(Clean_Data!$E$2:$E$301,Analysis!$A46,Clean_Data!$I$2:$I$301) -> 47717.638 | D46: =B46/(C46/1000) -> 0.48185021
A47: Sandy | B47: =AVERAGEIF(Clean_Data!$E$2:$E$301,Analysis!$A47,Clean_Data!$J$2:$J$301) -> 14.332812 | C47: =AVERAGEIF(Clean_Data!$E$2:$E$301,Analysis!$A47,Clean_Data!$I$2:$I$301) -> 47483.172 | D47: =B47/(C47/1000) -> 0.30185036
A48: Laterite | B48: =AVERAGEIF(Clean_Data!$E$2:$E$301,Analysis!$A48,Clean_Data!$J$2:$J$301) -> 14.638182 | C48: =AVERAGEIF(Clean_Data!$E$2:$E$301,Analysis!$A48,Clean_Data!$I$2:$I$301) -> 39765.509 | D48: =B48/(C48/1000) -> 0.36811252
A49: Black | B49: =AVERAGEIF(Clean_Data!$E$2:$E$301,Analysis!$A49,Clean_Data!$J$2:$J$301) -> 27.945902 | C49: =AVERAGEIF(Clean_Data!$E$2:$E$301,Analysis!$A49,Clean_Data!$I$2:$I$301) -> 43107.607 | D49: =B49/(C49/1000) -> 0.64828238
A56: Rainfall Impact Analysis
A57: Rainfall bands | B57: Average yield
A58: High(>900mm) | B58: =AVERAGEIF(Clean_Data!$M$2:$M$301,Analysis!A58,Clean_Data!$J$2:$J$301) -> 34.018293
A59: Medium(400-900mm) | B59: =AVERAGEIF(Clean_Data!$M$2:$M$301,Analysis!A59,Clean_Data!$J$2:$J$301) -> 17.723469
A60: Low(<400mm) | B60: =AVERAGEIF(Clean_Data!$M$2:$M$301,Analysis!A60,Clean_Data!$J$2:$J$301) -> 11.984167
A69: Year-wise Trend
A70: Year | B70: Total Records | C70: Average Yield | D70: Average Input Cost
A71: 2021 | B71: =COUNTIF(Clean_Data!$L:$L,Analysis!$A71) -> 87 | C71: =AVERAGEIF(Clean_Data!$L:$L,Analysis!$A71,Clean_Data!$J$2:$J$301) -> 21.636782 | D71: =AVERAGEIF(Clean_Data!$L:$L,Analysis!$A71,Clean_Data!$I:$I) -> 43275.931
A72: 2022 | B72: =COUNTIF(Clean_Data!$L:$L,Analysis!$A72) -> 105 | C72: =AVERAGEIF(Clean_Data!$L:$L,Analysis!$A72,Clean_Data!$J$2:$J$301) -> 19.297115 | D72: =AVERAGEIF(Clean_Data!$L:$L,Analysis!$A72,Clean_Data!$I:$I) -> 46816.086
A73: 2023 | B73: =COUNTIF(Clean_Data!$L:$L,Analysis!$A73) -> 108 | C73: =AVERAGEIF(Clean_Data!$L:$L,Analysis!$A73,Clean_Data!$J$2:$J$301) -> 19.086111 | D73: =AVERAGEIF(Clean_Data!$L:$L,Analysis!$A73,Clean_Data!$I:$I) -> 45805.843

Sheet Pivot_Backend    
A2: Crop Performance District-Cum-Seasonwise
A4: Season | B4: (All)
A6: Average of Yield_Quintal_per_Hectare | B6: District Type
A7: Crop Type | B7: Angul | C7: Balasore | D7: Bhadrak | E7: Cuttack | F7: Ganjam | G7: Jajpur | H7: Kendrapara | I7: Khordha | J7: Puri | K7: Sambalpur | L7: Grand Total
A8: Cotton | B8: 17.85 | C8: 14.26 | D8: 23.625 | F8: 24.65 | G8: 20.6 | H8: 26.225 | I8: 15.42 | J8: 24.02 | K8: 15.35 | L8: 20.421875
A9: Groundnut | B9: 35.233333 | C9: 16.766667 | D9: 21.1375 | E9: 34.05 | F9: 10.05 | G9: 26.1 | H9: 21.866667 | I9: 26.6 | J9: 15.2 | K9: 5.6 | L9: 22.567742
A10: Maize | B10: 21.133333 | C10: 17.6 | D10: 14.9 | E10: 25.675 | F10: 10.85 | G10: 13.05 | H10: 13.2 | I10: 21.042857 | J10: 16.9 | K10: 26.3 | L10: 18.947727
A11: Pulses | B11: 17.45 | C11: 20.357143 | D11: 23.166667 | E11: 16.842857 | F11: 19.7 | G11: 12.4 | H11: 29.12 | I11: 12.4 | J11: 22.55 | K11: 20.95 | L11: 19.84878
A12: Rice | B12: 8.35 | C12: 15.7 | D12: 18.2 | E12: 17.96 | F12: 17.7 | G12: 28.48 | H12: 26.4 | I12: 27.2 | J12: 13.525 | K12: 20 | L12: 19.283784
A13: Soybean | B13: 14.7 | C13: 15.6 | D13: 25.433333 | E13: 45.85 | F13: 17 | G13: 15.525 | H13: 23.066667 | I13: 27.75 | J13: 25.866667 | K13: 20.15 | L13: 21.148571
A14: Sugarcane | B14: 25.825 | C14: 33.65 | D14: 18.022222 | E14: 10.566667 | F14: 20.45 | G14: 11.34 | H14: 13.8 | I14: 16.225 | J14: 26.84 | K14: 34.8 | L14: 19.860465
A15: Wheat | B15: 20.32 | C15: 39.6 | D15: 23.633333 | E15: 20.45 | F15: 19.26 | G15: 19.85 | H15: 11.55 | I15: 6.7 | J15: 14.3 | K15: 13.93 | L15: 17.735135
A16: Grand Total | B16: 20.627586 | C16: 18.886667 | D16: 19.537778 | E16: 21.618519 | F16: 18.562069 | G16: 17.867857 | H16: 22.216 | I16: 19.9 | J16: 20.86 | K16: 19.359375 | L16: 19.881667
A18: Soil Type Performance
A19: Soil Types | B19: Average of Yield_Quintal_per_Hectare
A20: Alluvial | B20: 22.992754
A21: Black | B21: 27.945902
A22: Laterite | B22: 14.638182
A23: Red | B23: 18.645098
A24: Sandy | B24: 14.332812
A25: Grand Total | B25: 19.881667
A27: Year-wise Season Trend
A28: Sum of Yield_Quintal_per_Hectare | B28: Season
A29: Year | B29: Kharif | C29: Rabi | D29: Zaid | E29: Grand Total
A30: 2021 | B30: 708.8 | C30: 497.2 | D30: 380.7 | E30: 1586.7
A31: 2022 | B31: 1238 | C31: 516.8 | D31: 458.8 | E31: 2213.6
A32: 2023 | B32: 1113.5 | C32: 656.1 | D32: 394.6 | E32: 2164.2
A33: Grand Total | B33: 3060.3 | C33: 1670.1 | D33: 1234.1 | E33: 5964.5
A36: Irrigation Type Impact
A37: Crop_Type | B37: (All)
A39: Irrigation Type | B39: Average of Yield_Quintal_per_Hectare | C39: Count of Record_ID
A40: Canal | B40: 18.910714 | C40: 56
A41: Drip | B41: 18.196203 | C41: 79
A42: Rainfed | B42: 21.454651 | C42: 86
A43: Sprinkler | B43: 20.543038 | C43: 79
A44: Grand Total | B44: 19.881667 | C44: 300
A47: Rainfall Impact Analysis
A48: Rainfall Band | B48: Sum of Yield_Quintal_per_Hectare
A49: High(>900mm) | B49: 2789.5
A50: Low(<400mm) | B50: 1438.1
...

Sheet Dashboard
